Workbook

Sheet Setup
B2: Freelancer Finance Dashboard — Setup Guide
B4: Tax Year | C4: 2026
B5: Business Name (optional)
B6: State (for tax estimation)
B7: Filing Status | C7: Single
B22: Expense Categories Reference | C22: Description | D22: Deductibility
B23: Office Supplies | C23: Paper, ink, software subscriptions | D23: 100%
B24: Home Office | C24: Rent/utilities portion, internet | D24: % of sq footage
B25: Travel | C25: Client meetings, conferences | D25: 100% if business
B26: Meals & Entertainment | C26: Client meals | D26: 50%
B27: Professional Services | C27: Accountant, lawyer, contractor | D27: 100%
B28: Marketing & Advertising | C28: Website, ads, business cards | D28: 100%
B29: Insurance | C29: Business liability, health insurance | D29: 100% / varies
B30: Education & Training | C30: Courses, books, workshops | D30: 100%
B31: Equipment & Depreciation | C31: Computer, phone, furniture | D31: Section 179 / depreciation
B32: Vehicle & Transportation | C32: Mileage, parking, tolls | D32: 67¢/mile 2024
B33: Bank Fees & Interest | C33: Business account fees, loan interest | D33: 100%
B34: Taxes & Licenses | C34: Business licenses, professional fees | D34: 100% (not income tax)
B35: Step 5: Pay Quarterly Taxes
B36: Dashboard shows estimated payments. Deadlines: Apr 15, Jun 15, Sep 15, Jan 15.

Sheet Income
A3: # | B3: Date | C3: Invoice # | D3: Client | E3: Project/Description | F3: Gross Amount | G3: Platform Fee | H3: Net Received | I3: Notes
A4: 1 | B4: 2026-01-15 | C4: INV-001 | D4: Acme Corp | E4: Website redesign | F4: 5000 | G4: 0 | H4: =F4-G4 | I4: Milestone 1 payment
A5: 2 | B5: 2026-01-28 | C5: INV-002 | D5: TechStart Inc | E5: Mobile app UI | F5: 3500 | G5: 175 | H5: =F5-G5 | I5: Upwork fee 5%
A6: 3 | B6: 2026-02-10 | C6: INV-003 | D6: Acme Corp | E6: Website redesign | F6: 5000 | G6: 0 | H6: =F6-G6 | I6: Final payment
A7: 4 | B7: 2026-02-20 | C7: INV-004 | D7: MediaCo | E7: Video editing package | F7: 2800 | G7: 140 | H7: =F7-G7 | I7: Fiverr fee
A8: 5 | B8: 2026-03-05 | C8: INV-005 | D8: LocalShop | E8: Logo + brand kit | F8: 1500 | G8: 0 | H8: =F8-G8 | I8: Direct client
E9: TOTAL | F9: =SUM(F4:F8) | G9: =SUM(G4:G8) | H9: =SUM(H4:H8)
A10: =IF(F10="","",ROW()-3) | G10: =IF(F10="","",0) | H10: =IF(F10="","",F10-G10)
A11: =IF(F11="","",ROW()-3) | G11: =IF(F11="","",0) | H11: =IF(F11="","",F11-G11)
A12: =IF(F12="","",ROW()-3) | G12: =IF(F12="","",0) | H12: =IF(F12="","",F12-G12)
A13: =IF(F13="","",ROW()-3) | G13: =IF(F13="","",0) | H13: =IF(F13="","",F13-G13)
A14: =IF(F14="","",ROW()-3) | G14: =IF(F14="","",0) | H14: =IF(F14="","",F14-G14)
A15: =IF(F15="","",ROW()-3) | G15: =IF(F15="","",0) | H15: =IF(F15="","",F15-G15)
A16: =IF(F16="","",ROW()-3) | G16: =IF(F16="","",0) | H16: =IF(F16="","",F16-G16)
A17: =IF(F17="","",ROW()-3) | G17: =IF(F17="","",0) | H17: =IF(F17="","",F17-G17)
A18: =IF(F18="","",ROW()-3) | G18: =IF(F18="","",0) | H18: =IF(F18="","",F18-G18)
A19: =IF(F19="","",ROW()-3) | G19: =IF(F19="","",0) | H19: =IF(F19="","",F19-G19)
A20: =IF(F20="","",ROW()-3) | G20: =IF(F20="","",0) | H20: =IF(F20="","",F20-G20)
A21: =IF(F21="","",ROW()-3) | G21: =IF(F21="","",0) | H21: =IF(F21="","",F21-G21)
... A53: =IF(F53="","",ROW()-3) | G53: =IF(F53="","",0) | H53: =IF(F53="","",F53-G53)

Sheet Expenses
A3: # | B3: Date | C3: Vendor | D3: Category | E3: Description | F3: Amount | G3: Tax Deductible | H3: Deductible Amt | I3: Receipt? | J3: Notes
A4: 1 | B4: 2026-01-05 | C4: Adobe | D4: Office Supplies | E4: Creative Cloud subscription | F4: 54.99 | G4: Yes | H4: =IF(G4="Yes",F4,IF(G4="Partial",F4*0.5,0)) | I4: Y | J4: Monthly
A5: 2 | B5: 2026-01-10 | C5: WeWork | D5: Home Office | E5: Co-working space Jan | F5: 300 | G5: Yes | H5: =IF(G5="Yes",F5,IF(G5="Partial",F5*0.5,0)) | I5: Y | J5: 50% business use
A6: 3 | B6: 2026-01-15 | C6: Apple | D6: Equipment & Depreciation | E6: MacBook Pro | F6: 2499 | G6: Yes | H6: =IF(G6="Yes",F6,IF(G6="Partial",F6*0.5,0)) | I6: Y | J6: Section 179
A7: 4 | B7: 2026-01-20 | C7: Client Lunch | D7: Meals & Entertainment | E7: Meeting with Acme Corp | F7: 85 | G7: Partial | H7: =IF(G7="Yes",F7,IF(G7="Partial",F7*0.5,0)) | I7: Y | J7: 50% deductible
A8: 5 | B8: 2026-02-01 | C8: Google Ads | D8: Marketing & Advertising | E8: Google Ads Feb | F8: 200 | G8: Yes | H8: =IF(G8="Yes",F8,IF(G8="Partial",F8*0.5,0)) | I8: Y
A9: 6 | B9: 2026-02-05 | C9: Adobe | D9: Office Supplies | E9: Creative Cloud subscription | F9: 54.99 | G9: Yes | H9: =IF(G9="Yes",F9,IF(G9="Partial",F9*0.5,0)) | I9: Y | J9: Monthly
A10: 7 | B10: 2026-02-10 | C10: IRS Direct Pay | D10: Taxes & Licenses | E10: Q4 2025 estimated tax | F10: 1500 | G10: No | H10: =IF(G10="Yes",F10,IF(G10="Partial",F10*0.5,0)) | I10: Y | J10: Income tax not deductible
A11: 8 | B11: 2026-02-15 | C11: LinkedIn | D11: Marketing & Advertising | E11: LinkedIn Premium | F11: 59.99 | G11: Yes | H11: =IF(G11="Yes",F11,IF(G11="Partial",F11*0.5,0)) | I11: Y | J11: Business networking
A12: 9 | B12: 2026-03-01 | C12: Stripe | D12: Bank Fees & Interest | E12: Payment processing fees | F12: 127.5 | G12: Yes | H12: =IF(G12="Yes",F12,IF(G12="Partial",F12*0.5,0)) | I12: Y | J12: Feb transactions
A13: 10 | B13: 2026-03-05 | C13: Udemy | D13: Education & Training | E13: Advanced React course | F13: 19.99 | G13: Yes | H13: =IF(G13="Yes",F13,IF(G13="Partial",F13*0.5,0)) | I13: Y | J13: Skill development
D14: TOTAL | F14: =SUM(F4:F13) | H14: =SUM(H4:H13)
A15: =IF(F15="","",ROW()-3) | H15: =IF(G15="Yes",F15,IF(G15="Partial",F15*0.5,0))
A16: =IF(F16="","",ROW()-3) | H16: =IF(G16="Yes",F16,IF(G16="Partial",F16*0.5,0))
A17: =IF(F17="","",ROW()-3) | H17: =IF(G17="Yes",F17,IF(G17="Partial",F17*0.5,0))
A18: =IF(F18="","",ROW()-3) | H18: =IF(G18="Yes",F18,IF(G18="Partial",F18*0.5,0))
A19: =IF(F19="","",ROW()-3) | H19: =IF(G19="Yes",F19,IF(G19="Partial",F19*0.5,0))
A20: =IF(F20="","",ROW()-3) | H20: =IF(G20="Yes",F20,IF(G20="Partial",F20*0.5,0))
A21: =IF(F21="","",ROW()-3) | H21: =IF(G21="Yes",F21,IF(G21="Partial",F21*0.5,0))
A22: =IF(F22="","",ROW()-3) | H22: =IF(G22="Yes",F22,IF(G22="Partial",F22*0.5,0))
A23: =IF(F23="","",ROW()-3) | H23: =IF(G23="Yes",F23,IF(G23="Partial",F23*0.5,0))
A24: =IF(F24="","",ROW()-3) | H24: =IF(G24="Yes",F24,IF(G24="Partial",F24*0.5,0))
A25: =IF(F25="","",ROW()-3) | H25: =IF(G25="Yes",F25,IF(G25="Partial",F25*0.5,0))
A26: =IF(F26="","",ROW()-3) | H26: =IF(G26="Yes",F26,IF(G26="Partial",F26*0.5,0))
... A103: =IF(F103="","",ROW()-3) | H103: =IF(G103="Yes",F103,IF(G103="Partial",F103*0.5,0))

Sheet Dashboard
B2: Freelancer Finance Dashboard
B4: Total Income | C4: Total Expenses | D4: Net Profit | E4: Profit Margin | F4: Tax Deductions | G4: Est. Tax Due | H4: Quarterly Payment | I4: After-Tax Income
B5: =SUM(Income!H4:H8)+SUM(Income!H10:H53) | C5: =SUM(Expenses!F4:F13)+SUM(Expenses!F15:F103) | D5: =B5-C5 | E5: =IF(B5=0,0,D5/B5) | F5: =SUM(Expenses!H4:H13)+SUM(Expenses!H15:H103) | G5: =IF(D5<=0,0,D5*0.9235*0.153+MAX(0,D5-11600)*0.12+IF(D5>47150,(D5-47150)*0.1,0)) | H5: =G5/4 | I5: =D5-G5
B8: Monthly Income & Expense Summary
B9: Month | C9: Income | D9: Expenses | E9: Net Profit | F9: Cumulative
B10: January | C10: =SUMPRODUCT((MONTH(Income!$B$4:$B$8)=1)*(Income!$H$4:$H$8))+SUMPRODUCT((MONTH(Income!$B$10:$B$53)=1)*(Income!$H$10:$H$53)) | D10: =SUMPRODUCT((MONTH(Expenses!$B$4:$B$13)=1)*(Expenses!$F$4:$F$13))+SUMPRODUCT((MONTH(Expenses!$B$15:$B$103)=1)*(Expenses!$F$15:$F$103)) | E10: =C10-D10 | F10: =E10
B11: February | C11: =SUMPRODUCT((MONTH(Income!$B$4:$B$8)=2)*(Income!$H$4:$H$8))+SUMPRODUCT((MONTH(Income!$B$10:$B$53)=2)*(Income!$H$10:$H$53)) | D11: =SUMPRODUCT((MONTH(Expenses!$B$4:$B$13)=2)*(Expenses!$F$4:$F$13))+SUMPRODUCT((MONTH(Expenses!$B$15:$B$103)=2)*(Expenses!$F$15:$F$103)) | E11: =C11-D11 | F11: =F10+E11
B12: March | C12: =SUMPRODUCT((MONTH(Income!$B$4:$B$8)=3)*(Income!$H$4:$H$8))+SUMPRODUCT((MONTH(Income!$B$10:$B$53)=3)*(Income!$H$10:$H$53)) | D12: =SUMPRODUCT((MONTH(Expenses!$B$4:$B$13)=3)*(Expenses!$F$4:$F$13))+SUMPRODUCT((MONTH(Expenses!$B$15:$B$103)=3)*(Expenses!$F$15:$F$103)) | E12: =C12-D12 | F12: =F11+E12
B13: April | C13: =SUMPRODUCT((MONTH(Income!$B$4:$B$8)=4)*(Income!$H$4:$H$8))+SUMPRODUCT((MONTH(Income!$B$10:$B$53)=4)*(Income!$H$10:$H$53)) | D13: =SUMPRODUCT((MONTH(Expenses!$B$4:$B$13)=4)*(Expenses!$F$4:$F$13))+SUMPRODUCT((MONTH(Expenses!$B$15:$B$103)=4)*(Expenses!$F$15:$F$103)) | E13: =C13-D13 | F13: =F12+E13
B14: May | C14: =SUMPRODUCT((MONTH(Income!$B$4:$B$8)=5)*(Income!$H$4:$H$8))+SUMPRODUCT((MONTH(Income!$B$10:$B$53)=5)*(Income!$H$10:$H$53)) | D14: =SUMPRODUCT((MONTH(Expenses!$B$4:$B$13)=5)*(Expenses!$F$4:$F$13))+SUMPRODUCT((MONTH(Expenses!$B$15:$B$103)=5)*(Expenses!$F$15:$F$103)) | E14: =C14-D14 | F14: =F13+E14
B15: June | C15: =SUMPRODUCT((MONTH(Income!$B$4:$B$8)=6)*(Income!$H$4:$H$8))+SUMPRODUCT((MONTH(Income!$B$10:$B$53)=6)*(Income!$H$10:$H$53)) | D15: =SUMPRODUCT((MONTH(Expenses!$B$4:$B$13)=6)*(Expenses!$F$4:$F$13))+SUMPRODUCT((MONTH(Expenses!$B$15:$B$103)=6)*(Expenses!$F$15:$F$103)) | E15: =C15-D15 | F15: =F14+E15
B16: July | C16: =SUMPRODUCT((MONTH(Income!$B$4:$B$8)=7)*(Income!$H$4:$H$8))+SUMPRODUCT((MONTH(Income!$B$10:$B$53)=7)*(Income!$H$10:$H$53)) | D16: =SUMPRODUCT((MONTH(Expenses!$B$4:$B$13)=7)*(Expenses!$F$4:$F$13))+SUMPRODUCT((MONTH(Expenses!$B$15:$B$103)=7)*(Expenses!$F$15:$F$103)) | E16: =C16-D16 | F16: =F15+E16
B17: August | C17: =SUMPRODUCT((MONTH(Income!$B$4:$B$8)=8)*(Income!$H$4:$H$8))+SUMPRODUCT((MONTH(Income!$B$10:$B$53)=8)*(Income!$H$10:$H$53)) | D17: =SUMPRODUCT((MONTH(Expenses!$B$4:$B$13)=8)*(Expenses!$F$4:$F$13))+SUMPRODUCT((MONTH(Expenses!$B$15:$B$103)=8)*(Expenses!$F$15:$F$103)) | E17: =C17-D17 | F17: =F16+E17
B18: September | C18: =SUMPRODUCT((MONTH(Income!$B$4:$B$8)=9)*(Income!$H$4:$H$8))+SUMPRODUCT((MONTH(Income!$B$10:$B$53)=9)*(Income!$H$10:$H$53)) | D18: =SUMPRODUCT((MONTH(Expenses!$B$4:$B$13)=9)*(Expenses!$F$4:$F$13))+SUMPRODUCT((MONTH(Expenses!$B$15:$B$103)=9)*(Expenses!$F$15:$F$103)) | E18: =C18-D18 | F18: =F17+E18
B19: October | C19: =SUMPRODUCT((MONTH(Income!$B$4:$B$8)=10)*(Income!$H$4:$H$8))+SUMPRODUCT((MONTH(Income!$B$10:$B$53)=10)*(Income!$H$10:$H$53)) | D19: =SUMPRODUCT((MONTH(Expenses!$B$4:$B$13)=10)*(Expenses!$F$4:$F$13))+SUMPRODUCT((MONTH(Expenses!$B$15:$B$103)=10)*(Expenses!$F$15:$F$103)) | E19: =C19-D19 | F19: =F18+E19
B20: November | C20: =SUMPRODUCT((MONTH(Income!$B$4:$B$8)=11)*(Income!$H$4:$H$8))+SUMPRODUCT((MONTH(Income!$B$10:$B$53)=11)*(Income!$H$10:$H$53)) | D20: =SUMPRODUCT((MONTH(Expenses!$B$4:$B$13)=11)*(Expenses!$F$4:$F$13))+SUMPRODUCT((MONTH(Expenses!$B$15:$B$103)=11)*(Expenses!$F$15:$F$103)) | E20: =C20-D20 | F20: =F19+E20
B21: December | C21: =SUMPRODUCT((MONTH(Income!$B$4:$B$8)=12)*(Income!$H$4:$H$8))+SUMPRODUCT((MONTH(Income!$B$10:$B$53)=12)*(Income!$H$10:$H$53)) | D21: =SUMPRODUCT((MONTH(Expenses!$B$4:$B$13)=12)*(Expenses!$F$4:$F$13))+SUMPRODUCT((MONTH(Expenses!$B$15:$B$103)=12)*(Expenses!$F$15:$F$103)) | E21: =C21-D21 | F21: =F20+E21
B22: TOTAL | C22: =SUM(C10:C21) | D22: =SUM(D10:D21) | E22: =SUM(E10:E21) | F22: =F21
B24: Expense Breakdown by Category
B25: Category | C25: Total | D25: % of Total | E25: Deductible
B26: Office Supplies | C26: =SUMPRODUCT((Expenses!$D$4:$D$13="Office Supplies")*Expenses!$F$4:$F$13)+SUMPRODUCT((Expenses!$D$15:$D$103="Office Supplies")*Expenses!$F$15:$F$103) | D26: =IF(C38=0,0,C26/C38) | E26: =SUMPRODUCT((Expenses!$D$4:$D$13="Office Supplies")*Expenses!$H$4:$H$13)+SUMPRODUCT((Expenses!$D$15:$D$103="Office Supplies")*Expenses!$H$15:$H$103)
B27: Home Office | C27: =SUMPRODUCT((Expenses!$D$4:$D$13="Home Office")*Expenses!$F$4:$F$13)+SUMPRODUCT((Expenses!$D$15:$D$103="Home Office")*Expenses!$F$15:$F$103) | D27: =IF(C38=0,0,C27/C38) | E27: =SUMPRODUCT((Expenses!$D$4:$D$13="Home Office")*Expenses!$H$4:$H$13)+SUMPRODUCT((Expenses!$D$15:$D$103="Home Office")*Expenses!$H$15:$H$103)
B28: Travel | C28: =SUMPRODUCT((Expenses!$D$4:$D$13="Travel")*Expenses!$F$4:$F$13)+SUMPRODUCT((Expenses!$D$15:$D$103="Travel")*Expenses!$F$15:$F$103) | D28: =IF(C38=0,0,C28/C38) | E28: =SUMPRODUCT((Expenses!$D$4:$D$13="Travel")*Expenses!$H$4:$H$13)+SUMPRODUCT((Expenses!$D$15:$D$103="Travel")*Expenses!$H$15:$H$103)
B29: Meals & Entertainment | C29: =SUMPRODUCT((Expenses!$D$4:$D$13="Meals & Entertainment")*Expenses!$F$4:$F$13)+SUMPRODUCT((Expenses!$D$15:$D$103="Meals & Entertainment")*Expenses!$F$15:$F$103) | D29: =IF(C38=0,0,C29/C38) | E29: =SUMPRODUCT((Expenses!$D$4:$D$13="Meals & Entertainment")*Expenses!$H$4:$H$13)+SUMPRODUCT((Expenses!$D$15:$D$103="Meals & Entertainment")*Expenses!$H$15:$H$103)
B30: Professional Services | C30: =SUMPRODUCT((Expenses!$D$4:$D$13="Professional Services")*Expenses!$F$4:$F$13)+SUMPRODUCT((Expenses!$D$15:$D$103="Professional Services")*Expenses!$F$15:$F$103) | D30: =IF(C38=0,0,C30/C38) | E30: =SUMPRODUCT((Expenses!$D$4:$D$13="Professional Services")*Expenses!$H$4:$H$13)+SUMPRODUCT((Expenses!$D$15:$D$103="Professional Services")*Expenses!$H$15:$H$103)
B31: Marketing & Advertising | C31: =SUMPRODUCT((Expenses!$D$4:$D$13="Marketing & Advertising")*Expenses!$F$4:$F$13)+SUMPRODUCT((Expenses!$D$15:$D$103="Marketing & Advertising")*Expenses!$F$15:$F$103) | D31: =IF(C38=0,0,C31/C38) | E31: =SUMPRODUCT((Expenses!$D$4:$D$13="Marketing & Advertising")*Expenses!$H$4:$H$13)+SUMPRODUCT((Expenses!$D$15:$D$103="Marketing & Advertising")*Expenses!$H$15:$H$103)
B32: Insurance | C32: =SUMPRODUCT((Expenses!$D$4:$D$13="Insurance")*Expenses!$F$4:$F$13)+SUMPRODUCT((Expenses!$D$15:$D$103="Insurance")*Expenses!$F$15:$F$103) | D32: =IF(C38=0,0,C32/C38) | E32: =SUMPRODUCT((Expenses!$D$4:$D$13="Insurance")*Expenses!$H$4:$H$13)+SUMPRODUCT((Expenses!$D$15:$D$103="Insurance")*Expenses!$H$15:$H$103)
B33: Education & Training | C33: =SUMPRODUCT((Expenses!$D$4:$D$13="Education & Training")*Expenses!$F$4:$F$13)+SUMPRODUCT((Expenses!$D$15:$D$103="Education & Training")*Expenses!$F$15:$F$103) | D33: =IF(C38=0,0,C33/C38) | E33: =SUMPRODUCT((Expenses!$D$4:$D$13="Education & Training")*Expenses!$H$4:$H$13)+SUMPRODUCT((Expenses!$D$15:$D$103="Education & Training")*Expenses!$H$15:$H$103)
B34: Equipment & Depreciation | C34: =SUMPRODUCT((Expenses!$D$4:$D$13="Equipment & Depreciation")*Expenses!$F$4:$F$13)+SUMPRODUCT((Expenses!$D$15:$D$103="Equipment & Depreciation")*Expenses!$F$15:$F$103) | D34: =IF(C38=0,0,C34/C38) | E34: =SUMPRODUCT((Expenses!$D$4:$D$13="Equipment & Depreciation")*Expenses!$H$4:$H$13)+SUMPRODUCT((Expenses!$D$15:$D$103="Equipment & Depreciation")*Expenses!$H$15:$H$103)
B35: Vehicle & Transportation | C35: =SUMPRODUCT((Expenses!$D$4:$D$13="Vehicle & Transportation")*Expenses!$F$4:$F$13)+SUMPRODUCT((Expenses!$D$15:$D$103="Vehicle & Transportation")*Expenses!$F$15:$F$103) | D35: =IF(C38=0,0,C35/C38) | E35: =SUMPRODUCT((Expenses!$D$4:$D$13="Vehicle & Transportation")*Expenses!$H$4:$H$13)+SUMPRODUCT((Expenses!$D$15:$D$103="Vehicle & Transportation")*Expenses!$H$15:$H$103)
B36: Bank Fees & Interest | C36: =SUMPRODUCT((Expenses!$D$4:$D$13="Bank Fees & Interest")*Expenses!$F$4:$F$13)+SUMPRODUCT((Expenses!$D$15:$D$103="Bank Fees & Interest")*Expenses!$F$15:$F$103) | D36: =IF(C38=0,0,C36/C38) | E36: =SUMPRODUCT((Expenses!$D$4:$D$13="Bank Fees & Interest")*Expenses!$H$4:$H$13)+SUMPRODUCT((Expenses!$D$15:$D$103="Bank Fees & Interest")*Expenses!$H$15:$H$103)
B37: Taxes & Licenses | C37: =SUMPRODUCT((Expenses!$D$4:$D$13="Taxes & Licenses")*Expenses!$F$4:$F$13)+SUMPRODUCT((Expenses!$D$15:$D$103="Taxes & Licenses")*Expenses!$F$15:$F$103) | D37: =IF(C38=0,0,C37/C38) | E37: =SUMPRODUCT((Expenses!$D$4:$D$13="Taxes & Licenses")*Expenses!$H$4:$H$13)+SUMPRODUCT((Expenses!$D$15:$D$103="Taxes & Licenses")*Expenses!$H$15:$H$103)
B38: TOTAL | C38: =SUM(C26:C37) | D38: =SUM(D26:D37) | E38: =SUM(E26:E37)
B40: Top Clients by Revenue
B41: Client | C41: Total Revenue | D41: # Invoices | E41: Avg per Invoice
B42: Acme Corp | C42: =SUMIF(Income!$D$4:$D$53,"Acme Corp",Income!$H$4:$H$53) | D42: =COUNTIF(Income!$D$4:$D$53,"Acme Corp") | E42: =IF(D42=0,0,C42/D42)
B43: TechStart Inc | C43: =SUMIF(Income!$D$4:$D$53,"TechStart Inc",Income!$H$4:$H$53) | D43: =COUNTIF(Income!$D$4:$D$53,"TechStart Inc") | E43: =IF(D43=0,0,C43/D43)
B44: MediaCo | C44: =SUMIF(Income!$D$4:$D$53,"MediaCo",Income!$H$4:$H$53) | D44: =COUNTIF(Income!$D$4:$D$53,"MediaCo") | E44: =IF(D44=0,0,C44/D44)
B45: LocalShop | C45: =SUMIF(Income!$D$4:$D$53,"LocalShop",Income!$H$4:$H$53) | D45: =COUNTIF(Income!$D$4:$D$53,"LocalShop") | E45: =IF(D45=0,0,C45/D45)
B47: 2026 Quarterly Tax Payment Schedule
...
